#VRML_SIM R2023a utf8

EXTERNPROTO "https://raw.githubusercontent.com/cyberbotics/webots/R2023a/projects/objects/backgrounds/protos/TexturedBackground.proto"
EXTERNPROTO "https://raw.githubusercontent.com/cyberbotics/webots/R2023a/projects/objects/backgrounds/protos/TexturedBackgroundLight.proto"
EXTERNPROTO "https://raw.githubusercontent.com/cyberbotics/webots/R2023a/projects/objects/floors/protos/Floor.proto"

WorldInfo {
  basicTimeStep 64
}
Viewpoint {
  orientation -0.10017628489463692 0.10031003540463826 0.9899003024253648 0.88561618718774
  position -0.36091189831369586 -0.5262154921232749 0.1730746782030393
}
TexturedBackground {
}
TexturedBackgroundLight {
}
Floor {
  size 1 1
}
Solid {
  translation 0.00868439 -0.47706 5.9952e-15
  children [
    DEF WALL Shape {
      appearance DEF BLUE_WALL PBRAppearance {
        baseColor 0 0.0509804 1
        roughness 0.5
        metalness 0
      }
      geometry Box {
        size 1 0.05 0.1
      }
    }
  ]
  name "Wall"
}
Solid {
  translation -0.00153917 0.476799 0
  children [
    USE WALL
  ]
  name "Wall 2"
}
Solid {
  translation 0.484017 0.000280425 -8.88178e-16
  rotation 0 0 1 1.5708
  children [
    USE WALL
  ]
  name "Wall 3"
}
Solid {
  translation -0.476242 0.000147187 -1.5099e-14
  rotation 0 0 1 -1.5707953071795862
  children [
    USE WALL
  ]
  name "Wall 4"
}
PointLight {
  attenuation 0 0 1
  location 0 0.3 0
}
Robot {
  translation 0 0 0.05
  children [
    DistanceSensor {
      physics Physics {
      }
    }
    HingeJoint {
      jointParameters HingeJointParameters {
        axis 0 1 0
        anchor 0.05 -0.06 0
      }
      device [
        RotationalMotor {
          name "wheel4"
        }
      ]
      endPoint Solid {
        translation 0.05 0.06 0
        rotation 1 0 0 1.5708
        children [
          Shape {
            appearance PBRAppearance {
              baseColor 0 1 0
              roughness 1
              metalness 0
            }
            geometry Cylinder {
              height 0.02
              radius 0.04
            }
          }
        ]
      }
    }
    HingeJoint {
      jointParameters HingeJointParameters {
        axis 0 1 0
        anchor 0.05 -0.06 0
      }
      device [
        RotationalMotor {
          name "wheel4"
        }
      ]
      endPoint Solid {
        translation -0.05 0.0600003 6.74634e-14
        rotation 1 0 0 1.5708
        children [
          Shape {
            appearance PBRAppearance {
              baseColor 0 1 0
              roughness 1
              metalness 0
            }
            geometry Cylinder {
              height 0.02
              radius 0.04
            }
          }
        ]
        name "solid(1)"
      }
    }
    HingeJoint {
      jointParameters HingeJointParameters {
        axis 0 1 0
        anchor 0.05 -0.06 0
      }
      device [
        RotationalMotor {
          name "wheel4"
        }
      ]
      endPoint Solid {
        translation -0.05 -0.0599996 6.74634e-14
        rotation 1 0 0 1.5708
        children [
          Shape {
            appearance PBRAppearance {
              baseColor 0 1 0
              roughness 1
              metalness 0
            }
            geometry Cylinder {
              height 0.02
              radius 0.04
            }
          }
        ]
        name "solid(2)"
      }
    }
    HingeJoint {
      jointParameters HingeJointParameters {
        axis 0 1 0
        anchor 0.05 -0.06 0
      }
      device [
        RotationalMotor {
          name "wheel4"
        }
      ]
      endPoint Solid {
        translation 0.05 -0.0599996 6.74634e-14
        rotation 1 0 0 1.5708
        children [
          Shape {
            appearance PBRAppearance {
              baseColor 0 1 0
              roughness 1
              metalness 0
            }
            geometry Cylinder {
              height 0.02
              radius 0.04
            }
          }
        ]
        name "solid(3)"
      }
    }
    Shape {
      appearance PBRAppearance {
        baseColor 1 0 0
        roughness 1
        metalness 0
      }
      geometry Box {
        size 0.2 0.1 0.05
      }
    }
  ]
  physics Physics {
  }
}
